[2023-12-13T12:29:44.352+0000] {taskinstance.py:1159} INFO - Dependencies all met for dep_context=non-requeueable deps ti=<TaskInstance: tafmis_test_data_fetch.get_token manual__2023-12-13T12:29:42.998291+00:00 [queued]>
[2023-12-13T12:29:44.366+0000] {taskinstance.py:1159} INFO - Dependencies all met for dep_context=requeueable deps ti=<TaskInstance: tafmis_test_data_fetch.get_token manual__2023-12-13T12:29:42.998291+00:00 [queued]>
[2023-12-13T12:29:44.367+0000] {taskinstance.py:1361} INFO - Starting attempt 1 of 1
[2023-12-13T12:29:44.389+0000] {taskinstance.py:1382} INFO - Executing <Task(_PythonDecoratedOperator): get_token> on 2023-12-13 12:29:42.998291+00:00
[2023-12-13T12:29:44.398+0000] {standard_task_runner.py:57} INFO - Started process 337 to run task
[2023-12-13T12:29:44.408+0000] {standard_task_runner.py:84} INFO - Running: ['***', 'tasks', 'run', 'tafmis_test_data_fetch', 'get_token', 'manual__2023-12-13T12:29:42.998291+00:00', '--job-id', '16', '--raw', '--subdir', 'DAGS_FOLDER/tafmis_test.py', '--cfg-path', '/tmp/tmp06m5p0yf']
[2023-12-13T12:29:44.410+0000] {standard_task_runner.py:85} INFO - Job 16: Subtask get_token
[2023-12-13T12:29:44.492+0000] {task_command.py:416} INFO - Running <TaskInstance: tafmis_test_data_fetch.get_token manual__2023-12-13T12:29:42.998291+00:00 [running]> on host 67519c681eff
[2023-12-13T12:29:44.664+0000] {taskinstance.py:1662} INFO - Exporting env vars: AIRFLOW_CTX_DAG_OWNER='***' AIRFLOW_CTX_DAG_ID='tafmis_test_data_fetch' AIRFLOW_CTX_TASK_ID='get_token' AIRFLOW_CTX_EXECUTION_DATE='2023-12-13T12:29:42.998291+00:00' AIRFLOW_CTX_TRY_NUMBER='1' AIRFLOW_CTX_DAG_RUN_ID='manual__2023-12-13T12:29:42.998291+00:00'
[2023-12-13T12:29:44.665+0000] {taskinstance.py:1937} ERROR - Task failed with exception
Traceback (most recent call last):
  File "/home/airflow/.local/lib/python3.8/site-packages/airflow/decorators/base.py", line 221, in execute
    return_value = super().execute(context)
  File "/home/airflow/.local/lib/python3.8/site-packages/airflow/operators/python.py", line 192, in execute
    return_value = self.execute_callable()
  File "/home/airflow/.local/lib/python3.8/site-packages/airflow/operators/python.py", line 209, in execute_callable
    return self.python_callable(*self.op_args, **self.op_kwargs)
  File "/opt/airflow/dags/tafmis_test.py", line 20, in get_token
    token_url = token_url
UnboundLocalError: local variable 'token_url' referenced before assignment
[2023-12-13T12:29:44.685+0000] {taskinstance.py:1400} INFO - Marking task as FAILED. dag_id=tafmis_test_data_fetch, task_id=get_token, execution_date=20231213T122942, start_date=20231213T122944, end_date=20231213T122944
[2023-12-13T12:29:44.707+0000] {standard_task_runner.py:104} ERROR - Failed to execute job 16 for task get_token (local variable 'token_url' referenced before assignment; 337)
[2023-12-13T12:29:44.737+0000] {local_task_job_runner.py:228} INFO - Task exited with return code 1
[2023-12-13T12:29:44.783+0000] {taskinstance.py:2778} INFO - 0 downstream tasks scheduled from follow-on schedule check
