[2023-12-13T12:36:25.837+0000] {taskinstance.py:1159} INFO - Dependencies all met for dep_context=non-requeueable deps ti=<TaskInstance: tafmis_test_data_fetch.get_token manual__2023-12-13T12:36:23.253053+00:00 [queued]>
[2023-12-13T12:36:25.865+0000] {taskinstance.py:1159} INFO - Dependencies all met for dep_context=requeueable deps ti=<TaskInstance: tafmis_test_data_fetch.get_token manual__2023-12-13T12:36:23.253053+00:00 [queued]>
[2023-12-13T12:36:25.865+0000] {taskinstance.py:1361} INFO - Starting attempt 1 of 1
[2023-12-13T12:36:25.907+0000] {taskinstance.py:1382} INFO - Executing <Task(_PythonDecoratedOperator): get_token> on 2023-12-13 12:36:23.253053+00:00
[2023-12-13T12:36:25.916+0000] {standard_task_runner.py:57} INFO - Started process 63 to run task
[2023-12-13T12:36:25.930+0000] {standard_task_runner.py:84} INFO - Running: ['***', 'tasks', 'run', 'tafmis_test_data_fetch', 'get_token', 'manual__2023-12-13T12:36:23.253053+00:00', '--job-id', '19', '--raw', '--subdir', 'DAGS_FOLDER/tafmis_test.py', '--cfg-path', '/tmp/tmpn8rirb1o']
[2023-12-13T12:36:25.931+0000] {standard_task_runner.py:85} INFO - Job 19: Subtask get_token
[2023-12-13T12:36:26.174+0000] {task_command.py:416} INFO - Running <TaskInstance: tafmis_test_data_fetch.get_token manual__2023-12-13T12:36:23.253053+00:00 [running]> on host 67519c681eff
[2023-12-13T12:36:26.399+0000] {taskinstance.py:1662} INFO - Exporting env vars: AIRFLOW_CTX_DAG_OWNER='***' AIRFLOW_CTX_DAG_ID='tafmis_test_data_fetch' AIRFLOW_CTX_TASK_ID='get_token' AIRFLOW_CTX_EXECUTION_DATE='2023-12-13T12:36:23.253053+00:00' AIRFLOW_CTX_TRY_NUMBER='1' AIRFLOW_CTX_DAG_RUN_ID='manual__2023-12-13T12:36:23.253053+00:00'
[2023-12-13T12:38:35.670+0000] {taskinstance.py:1937} ERROR - Task failed with exception
Traceback (most recent call last):
  File "/home/airflow/.local/lib/python3.8/site-packages/urllib3/connection.py", line 174, in _new_conn
    conn = connection.create_connection(
  File "/home/airflow/.local/lib/python3.8/site-packages/urllib3/util/connection.py", line 95, in create_connection
    raise err
  File "/home/airflow/.local/lib/python3.8/site-packages/urllib3/util/connection.py", line 85, in create_connection
    sock.connect(sa)
TimeoutError: [Errno 110] Connection timed out

During handling of the above exception, another exception occurred:

Traceback (most recent call last):
  File "/home/airflow/.local/lib/python3.8/site-packages/urllib3/connectionpool.py", line 715, in urlopen
    httplib_response = self._make_request(
  File "/home/airflow/.local/lib/python3.8/site-packages/urllib3/connectionpool.py", line 404, in _make_request
    self._validate_conn(conn)
  File "/home/airflow/.local/lib/python3.8/site-packages/urllib3/connectionpool.py", line 1058, in _validate_conn
    conn.connect()
  File "/home/airflow/.local/lib/python3.8/site-packages/urllib3/connection.py", line 363, in connect
    self.sock = conn = self._new_conn()
  File "/home/airflow/.local/lib/python3.8/site-packages/urllib3/connection.py", line 186, in _new_conn
    raise NewConnectionError(
urllib3.exceptions.NewConnectionError: <urllib3.connection.HTTPSConnection object at 0x7f95df20e040>: Failed to establish a new connection: [Errno 110] Connection timed out

During handling of the above exception, another exception occurred:

Traceback (most recent call last):
  File "/home/airflow/.local/lib/python3.8/site-packages/requests/adapters.py", line 486, in send
    resp = conn.urlopen(
  File "/home/airflow/.local/lib/python3.8/site-packages/urllib3/connectionpool.py", line 799, in urlopen
    retries = retries.increment(
  File "/home/airflow/.local/lib/python3.8/site-packages/urllib3/util/retry.py", line 592, in increment
    raise MaxRetryError(_pool, url, error or ResponseError(cause))
urllib3.exceptions.MaxRetryError: HTTPSConnectionPool(host='api.ahe.r.mil.uk', port=443): Max retries exceeded with url: /connect/token (Caused by NewConnectionError('<urllib3.connection.HTTPSConnection object at 0x7f95df20e040>: Failed to establish a new connection: [Errno 110] Connection timed out'))

During handling of the above exception, another exception occurred:

Traceback (most recent call last):
  File "/home/airflow/.local/lib/python3.8/site-packages/airflow/decorators/base.py", line 221, in execute
    return_value = super().execute(context)
  File "/home/airflow/.local/lib/python3.8/site-packages/airflow/operators/python.py", line 192, in execute
    return_value = self.execute_callable()
  File "/home/airflow/.local/lib/python3.8/site-packages/airflow/operators/python.py", line 209, in execute_callable
    return self.python_callable(*self.op_args, **self.op_kwargs)
  File "/opt/airflow/dags/tafmis_test.py", line 24, in get_token
    access_token_response = requests.post(token_url,
  File "/home/airflow/.local/lib/python3.8/site-packages/requests/api.py", line 115, in post
    return request("post", url, data=data, json=json, **kwargs)
  File "/home/airflow/.local/lib/python3.8/site-packages/requests/api.py", line 59, in request
    return session.request(method=method, url=url, **kwargs)
  File "/home/airflow/.local/lib/python3.8/site-packages/requests/sessions.py", line 589, in request
    resp = self.send(prep, **send_kwargs)
  File "/home/airflow/.local/lib/python3.8/site-packages/requests/sessions.py", line 703, in send
    r = adapter.send(request, **kwargs)
  File "/home/airflow/.local/lib/python3.8/site-packages/requests/adapters.py", line 519, in send
    raise ConnectionError(e, request=request)
requests.exceptions.ConnectionError: HTTPSConnectionPool(host='api.ahe.r.mil.uk', port=443): Max retries exceeded with url: /connect/token (Caused by NewConnectionError('<urllib3.connection.HTTPSConnection object at 0x7f95df20e040>: Failed to establish a new connection: [Errno 110] Connection timed out'))
[2023-12-13T12:38:35.683+0000] {taskinstance.py:1400} INFO - Marking task as FAILED. dag_id=tafmis_test_data_fetch, task_id=get_token, execution_date=20231213T123623, start_date=20231213T123625, end_date=20231213T123835
[2023-12-13T12:38:35.702+0000] {standard_task_runner.py:104} ERROR - Failed to execute job 19 for task get_token (HTTPSConnectionPool(host='api.ahe.r.mil.uk', port=443): Max retries exceeded with url: /connect/token (Caused by NewConnectionError('<urllib3.connection.HTTPSConnection object at 0x7f95df20e040>: Failed to establish a new connection: [Errno 110] Connection timed out')); 63)
[2023-12-13T12:38:35.736+0000] {local_task_job_runner.py:228} INFO - Task exited with return code 1
[2023-12-13T12:38:35.763+0000] {taskinstance.py:2778} INFO - 0 downstream tasks scheduled from follow-on schedule check
